Workbook

Sheet Istruzioni
B2: Registro stampa · Vivere più a lungo: sport e intelligenza artificiale, Taranto, 10 e 11 dicembre 2026
B3: Fondazione bioERGOtech ETS. Strumento interno, da non inviare.
B5: Come si usa
B6: 1. “Media list”: le testate sono già verificate. Compila le celle gialle: referente, email, telefono, date di invio, risposta, accredito.
B7: 2. “Uscite”: una riga per ogni articolo, servizio TV o radio, post di una testata. Le prime righe sono le uscite già pubblicate e verificate.
B8: 3. Per ogni uscita salva una copia (PDF o screenshot) e scrivi il nome del file nella colonna “File”. Servirà per la rassegna stampa.
B9: 4. “Riepilogo” si aggiorna da solo: sono formule. Non scrivere in quel foglio.
B11: Regole
B12: Celle gialle: da compilare. Le altre colonne della media list vengono dalla verifica di ottobre 2026: correggile se una testata cambia.
B13: Nessun dato personale di giornalisti senza il loro consenso: indirizzi e telefoni diretti solo se te li danno loro.
B14: Copertura: riporta titolo e link. Il testo integrale degli articoli va solo nella rassegna interna o per gli sponsor, se la testata lo consente.
B15: Numeri di lettori o ascolti: solo se dichiarati dalla fonte. Mai stimati.
... B20: Esempio di cella da compilare

Sheet Media list
A1: Testata | B1: Tipo | C1: Area | D1: Temi | E1: Priorità | F1: Perché | G1: Sito | H1: Pagina contatti | I1: Email redazione (pubblica) | J1: Fonte dell’email | K1: Referente | L1: Email referente | M1: Telefono | N1: Comunicato inviato il | O1: Nota inviata il | P1: Risposta | Q1: Accreditato | R1: Note
A2: Antenna Sud | B2: TV regionale e sito di notizie (Canale 85 S.r.l.) | C2: Bari, BAT, Brindisi, Lecce, Foggia, Taranto, Potenza, Matera | D2: cronaca, attualità, sport, segnalazioni | E2: A | F2: Ha seguito la riapertura del PalaMazzola (27 luglio 2026): copertura TV su Taranto e province vicine. | G2: https://www.antennasud.com/ | I2: info@antennasud.com | J2: https://www.antennasud.com/ (footer, voce “Contatti”; indirizzo protetto, decodificato; /contatti/ risponde 404; il dominio canale85.it reindirizza qui; consultato 7 ott 2026)
A3: Adnkronos (anche Adnkronos Salute) | B3: Agenzia di stampa nazionale | C3: Italia | D3: politica, salute, sport, economia | E3: A | F3: Ha già diffuso la presentazione della Fondazione alla Camera (27 ottobre 2025); ha una redazione Salute. | G3: https://www.adnkronos.com/ | H3: https://www.adnkronos.com/contatti | I3: segreteria.redazione@adnkronos.com; salute@adnkronos.com | J3: https://www.adnkronos.com/contatti (voci “Adnkronos Agenzia” e “Adnkronos Salute”; consultato 7 ott 2026)
A4: Agenzia Dire | B4: Agenzia di stampa nazionale con redazioni regionali e tematiche | C4: Italia; redazione regionale Puglia | D4: politica, sanità, welfare, scuola, giovani | E4: A | F4: Redazioni dedicate a Puglia, scuola e sanità: copre i tre aspetti del progetto. | G4: https://www.dire.it/ | H4: https://www.dire.it/contatti/ | I4: regione.puglia@dire.it; scuola@dire.it; sanita@dire.it | J4: https://www.dire.it/contatti/ (voci “Puglia”, “Scuola”, “Sanità”; consultato 7 ott 2026)
A5: AGI (redazione di Bari) | B5: Agenzia di stampa nazionale | C5: Italia; sede di Bari | D5: cronaca, politica, economia, sport | E5: A | F5: Agenzia nazionale con sede a Bari: utile per il lancio regionale e nazionale. | G5: https://www.agi.it/ | H5: https://www.agi.it/info/sedi/ | I5: redazione.bari@agi.it | J5: https://www.agi.it/info/sedi/ (voce “Bari”; consultato 7 ott 2026)
A6: Quotidiano di Puglia | B6: Quotidiano regionale con edizioni locali | C6: Lecce, Brindisi, Taranto, Bari, BAT, Foggia | D6: cronaca, politica, economia, sport | E6: A | F6: Edizione di Taranto con redazione dedicata: canale diretto per la cronaca cittadina. | G6: https://www.quotidianodipuglia.it/ | H6: https://www.quotidianodipuglia.it/redazione/ | J6: La pagina redazione riporta solo indirizzi nominativi di giornalisti, volutamente non raccolti (consultato 7 ott 2026).
A7: Il Farmacista Online | B7: Testata online della professione (notizie quotidiane dalla FOFI) | C7: Nazionale | D7: Federazione e Ordini, professione, scienza e farmaci | E7: A | F7: Notizie quotidiane dalla FOFI: interviene il presidente FOFI Andrea Mandelli. | G7: https://www.ilfarmacistaonline.it/ | H7: https://www.ilfarmacistaonline.it/redazione.php | J7: La pagina redazione riporta solo l’indirizzo generale dell’editore, non della redazione: non raccolto (consultato 7 ott 2026).
A8: Innlifes | B8: Testata online sull’innovazione nelle scienze della vita | C8: Nazionale | D8: biotecnologie, startup, innovazione in salute | E8: A | F8: Ha già pubblicato un profilo del Presidente (29 ottobre 2025); segue biotecnologie e startup. | G8: https://www.innlifes.com/ | H8: https://www.innlifes.com/contatti/ | I8: redazione@innlifes.com | J8: https://www.innlifes.com/contatti/ (“Se vuoi segnalare un progetto, un evento o un comunicato stampa”; consultato 7 ott 2026)
A9: La Tecnica della Scuola | B9: Testata e casa editrice sulla scuola (sede a Catania) | C9: Nazionale | D9: scuola, docenti, concorsi, didattica | E9: A | F9: Informazione per il mondo della scuola: adatta al bando del programma scuole. | G9: https://www.tecnicadellascuola.it/ | H9: https://www.tecnicadellascuola.it/contatti | I9: info@tecnicadellascuola.it | J9: https://www.tecnicadellascuola.it/contatti (indirizzo generale della casa editrice; consultato 7 ott 2026)
A10: Orizzonte Scuola | B10: Quotidiano online sulla scuola | C10: Nazionale | D10: scuola, docenti, studenti, normativa | E10: A | F10: Quotidiano online sulla scuola: canale per far conoscere il programma gratuito a docenti e dirigenti. | G10: https://www.orizzontescuola.it/ | J10: Home e contatti protetti da verifica anti bot (403); sito verificato tramite feed https://www.orizzontescuola.it/feed/ (consultato 7 ott 2026).
A11: Skuola.net | B11: Portale per studenti | C11: Nazionale | D11: studenti, scuola, orientamento, università | E11: A | F11: Portale rivolto agli studenti: parla ai destinatari del programma. | G11: https://www.skuola.net/ | H11: https://corporate.skuola.net/contatti/ | I11: redazione@skuola.net | J11: https://corporate.skuola.net/contatti/ (consultato 7 ott 2026)
A12: Vita | B12: Magazine e portale del non profit | C12: Nazionale | D12: non profit, volontariato, welfare, salute, formazione | E12: A | F12: Testata del terzo settore: la Fondazione è un ETS e il programma scuole è gratuito. | G12: https://www.vita.it/ | H12: https://www.vita.it/info-e-contatti/ | I12: redazione@vita.it | J12: https://www.vita.it/info-e-contatti/ (voce “Redazione”; indirizzo protetto, decodificato; consultato 7 ott 2026)
A13: Telenorba (TG Norba) | B13: TV regionale e canale all news TG Norba 24 | C13: Puglia (sede a Conversano, BA) | D13: cronaca, politica, attualità, eventi, sport | E13: A | F13: Ha dedicato un servizio all’incontro di Taranto del dicembre 2025 (Fondazione non nominata nel testo online); sezione “Eventi e incontri”. | G13: https://telenorba.it/ | H13: https://telenorba.it/contatti/ | J13: Nessun indirizzo sulla pagina contatti; per gli eventi c’è il modulo https://telenorba.it/pubblica-il-tuo-evento/ (consultati 7 ott 2026).
A14: ANSA Puglia | B14: Agenzia di stampa, redazione regionale | C14: Puglia (sede di Bari) | D14: cronaca, politica, sanità regionale, economia | E14: A | F14: Un lancio ANSA viene ripreso da molte testate locali e nazionali. | G14: https://www.ansa.it/puglia/ | H14: https://www.ansa.it/corporate/it/info/dove_siamo.html | I14: ansa.bari@ansa.it | J14: https://www.ansa.it/puglia/ (box contatti della redazione regionale, con indirizzo di Bari confermato da dove_siamo.html; consultati 7 ott 2026)
A15: La Gazzetta del Mezzogiorno | B15: Quotidiano regionale con edizioni provinciali | C15: Puglia e Basilicata; redazione di Taranto | D15: cronaca, politica, economia, salute, sport | E15: A | F15: Quotidiano regionale con redazione a Taranto e sezione salute; ha già scritto del Presidente (17 ottobre 2022). | G15: https://www.lagazzettadelmezzogiorno.it/ | H15: https://www.lagazzettadelmezzogiorno.it/sezioni/477/info-e-contatti | I15: redazione.taranto@gazzettamezzogiorno.it; sport@gazzettamezzogiorno.it | J15: https://www.lagazzettadelmezzogiorno.it/sezioni/477/info-e-contatti (voci “Gazzetta Taranto” e “Sport”; consultato 7 ott 2026)
A16: TGR Puglia (Rai) | B16: Telegiornale regionale Rai | C16: Puglia, sede di Bari | D16: cronaca, politica, economia, cultura, sport | E16: A | F16: Servizio pubblico regionale: copertura televisiva e immagini delle due giornate. | G16: https://www.rainews.it/tgr/puglia | H16: https://www.rainews.it/tgr/chi-siamo.html | I16: tgrpuglia@rai.it | J16: https://www.rainews.it/tgr/chi-siamo.html (elenco redazioni, voce “Puglia”; consultato 7 ott 2026)
A17: Corriere di Taranto | B17: Quotidiano online | C17: Taranto | D17: politica e amministrazione, industria, cronaca, cultura | E17: A | F17: Testata cittadina attenta a politica locale e industria: adatta al racconto dell’evento a Taranto. | G17: https://www.corriereditaranto.it/ | I17: redazione@corriereditaranto.it | J17: https://www.corriereditaranto.it/ (footer, voce “Comunica con noi”; indirizzo protetto da Cloudflare, decodificato; /contatti/ rimanda alla home; consultato 7 ott 2026)
A18: TarantoToday | B18: Quotidiano digitale (rete Citynews) | C18: Taranto e provincia | D18: cronaca, attualità, salute, sport, eventi | E18: A | F18: Ha già scritto della Fondazione (22 aprile 2025); accoglie segnalazioni di eventi. | G18: https://www.tarantotoday.it/ | H18: https://www.citynews.it/gruppo/redazioni/tarantotoday.html | I18: tarantotoday@citynews.it | J18: https://www.citynews.it/gruppo/redazioni/tarantotoday.html (“Scrivi alla redazione per segnalare notizie ed eventi”; consultato 7 ott 2026)
A19: Buonasera24 (testata “Buonasera”) | B19: Testata locale online, con gallery e video | C19: Taranto; anche Bari, BAT, Lecce, Brindisi | D19: cronaca, politica, attualità, scuola, sanità | E19: A | F19: Ha già scritto del Presidente (2022), della Fondazione (2025) e della rete delle scuole (22 settembre 2026). | G19: https://www.buonasera24.it/ | I19: redazione.taranto@buonasera24.it | J19: https://www.buonasera24.it/ (footer del sito, voce “Email”; la pagina /contatti risponde 404; consultato 7 ott 2026)
A20: Studio 100 TV | B20: TV locale (canale 98) e sito di notizie | C20: Taranto; anche Brindisi, BAT e Bari | D20: telegiornale, sport, salute, eventi | E20: A | F20: Si presenta come “la storica TV di Taranto”; ha seguito i Taranto Biotech Days 2024 e la presentazione a Montecitorio (29 ottobre 2025). | G20: https://www.studio100.it/ | H20: https://www.studio100.it/contatti/ | I20: redazione@studio100.it | J20: https://www.studio100.it/contatti/ (voce “Redazione”; consultato 7 ott 2026)
A21: la Repubblica Bari | B21: Edizione locale di quotidiano nazionale | C21: Bari e Puglia | D21: cronaca, politica, cultura | E21: B | F21: Edizione regionale di un quotidiano nazionale: adatta a una notizia di respiro pugliese. | G21: https://bari.repubblica.it/ | H21: https://www.repubblica.it/static/servizi/scrivi.html | J21: La pagina “Scrivi alla redazione” riporta solo indirizzi nazionali, non della redazione di Bari (consultato 7 ott 2026).
A22: TeleRama News (TRNews) | B22: TV regionale TeleRama e sito di notizie | C22: Lecce, Brindisi, Taranto, Bari | D22: cronaca, politica, sport, attualità, eventi | E22: B | F22: Ha dedicato un servizio TV alla rete delle scuole (24 settembre 2026), senza nominare la Fondazione nel testo online. | G22: https://trnews.it/ | H22: https://trnews.it/redazione | J22: La pagina redazione non riporta un indirizzo generico; c’è il canale “Dillo a TeleRama” (consultato 7 ott 2026).
A23: AI4Business | B23: Testata online sull’intelligenza artificiale (Network Digital360) | C23: Nazionale | D23: intelligenza artificiale, impresa | E23: B | F23: Dedicata all’IA: adatta ai panel su IA e salute e al programma scuole. | G23: https://www.ai4business.it/ | H23: https://www.ai4business.it/about/ | I23: redazione@ai4business.it | J23: https://www.ai4business.it/about/ (“Segreteria di redazione”; consultato 7 ott 2026)
A24: Avvenire | B24: Quotidiano nazionale | C24: Nazionale | D24: cronache nazionali, cultura e sport, informazione religiosa | E24: B | F24: Quotidiano nazionale con redazioni per cronache e per cultura e sport. | G24: https://www.avvenire.it/ | H24: https://www.avvenire.it/info/contatti | I24: segreteria.redazione@avvenire.it; interni@avvenire.it | J24: https://www.avvenire.it/info/contatti (voci “Segreteria di redazione” e “Cronache nazionali”; consultato 7 ott 2026)
A25: Buone Notizie (Corriere della Sera) | B25: Sezione del Corriere della Sera dedicata al terzo settore | C25: Nazionale | D25: associazioni, volontariato, terzo settore | E25: B | F25: Valorizza realtà del terzo settore: adatta alla storia di una fondazione ETS di Taranto. | G25: https://www.corriere.it/buone-notizie/ | H25: https://www.corriere.it/buone-notizie/chi-siamo.shtml | I25: buonenotizie@corriere.it | J25: https://www.corriere.it/buone-notizie/chi-siamo.shtml (“puoi segnalarla a”; consultato 7 ott 2026)
A26: EconomyUp | B26: Testata online (Network Digital360) | C26: Nazionale | D26: innovazione, startup, impresa | E26: B | F26: Racconta innovazione e startup: angolo biotecnologie e IA a Taranto. | G26: https://www.economyup.it/ | H26: https://www.economyup.it/about/ | I26: redazione@economyup.it | J26: https://www.economyup.it/about/ (consultato 7 ott 2026)
A27: Farmacista33 | B27: Portale di informazione per farmacisti | C27: Nazionale | D27: professione, farmaci, aggiornamento | E27: B | F27: Portale per farmacisti: aggancio con l’intervento del presidente FOFI. | G27: https://www.farmacista33.it/ | H27: https://www.farmacista33.it/contatti/ | J27: Solo modulo contatti, nessun indirizzo (consultato 7 ott 2026).
A28: HealthTech 360 | B28: Testata online (Network Digital360) | C28: Nazionale | D28: sanità digitale, innovazione, dispositivi indossabili | E28: B | F28: Sanità digitale e intelligenza artificiale: angolo tecnologico della prima giornata. | G28: https://www.healthtech360.it/ | H28: https://www.healthtech360.it/about/ | I28: info@healthtech360.it | J28: https://www.healthtech360.it/about/ (“Segreteria di redazione”; consultato 7 ott 2026)
A29: Insalutenews | B29: Quotidiano online di informazione medica | C29: Nazionale | D29: medicina, prevenzione, ricerca | E29: B | F29: Pubblica notizie di prevenzione e ricerca per il pubblico generale. | G29: https://www.insalutenews.it/in-salute/ | H29: https://www.insalutenews.it/in-salute/contatti/ | I29: redazione@insalutenews.it | J29: https://www.insalutenews.it/in-salute/contatti/ (voce “Redazione”; consultato 7 ott 2026)
A30: OA Sport | B30: Testata online di sport olimpici | C30: Nazionale | D30: discipline olimpiche (nuoto, ginnastica, atletica e altre) | E30: B | F30: Segue le discipline olimpiche: tra i relatori Aldo Montano, Valentina Vezzali, Agostino Abbagnale, Manuel Bortuzzo. | G30: https://www.oasport.it/ | H30: https://www.oasport.it/chi-siamo/ | J30: La pagina “Chi siamo” non riporta indirizzi (consultato 7 ott 2026).
A31: Osservatorio Terapie Avanzate | B31: Portale di informazione (RARE LAB S.r.l.) | C31: Nazionale | D31: terapie cellulari e geniche, editing genomico, terapie digitali | E31: B | F31: Ha segnalato in agenda i Taranto Biotech Days 2024; segue terapie cellulari e geniche, temi vicini alla missione della Fondazione. | G31: https://www.osservatorioterapieavanzate.it/ | J31: Pagina contatti non aperta (protezione anti robot); l’indirizzo email è oscurato sul sito (consultato 7 ott 2026).
A32: Pianeta Salute | B32: Magazine online di Pianeta Salute TV | C32: Nazionale | D32: salute, ricerca, sanità, sport | E32: B | F32: Ha già presentato la Fondazione (3 novembre 2025); unisce salute e sport. | G32: https://pianetasalute.online/ | H32: https://pianetasalute.online/contatti/ | I32: info@pianetasalute.online | J32: https://pianetasalute.online/contatti/ (“Per mettersi in contatto con la Redazione”; consultato 7 ott 2026)
A33: Quotidiano Sanità | B33: Quotidiano online di informazione sanitaria | C33: Nazionale | D33: politica sanitaria, professioni, scienza e farmaci | E33: B | F33: Testata nazionale di informazione sanitaria: adatta al tema prevenzione e innovazione. | G33: https://www.quotidianosanita.it/ | J33: Nessuna pagina contatti aperta (la pagina “chi siamo” risponde 404); c’è solo il modulo “Scrivi al direttore” (consultato 7 ott 2026).
A34: Sanità Informazione | B34: Quotidiano online e settimanale di approfondimento | C34: Nazionale | D34: salute, prevenzione, professioni, one health | E34: B | F34: Ha una sezione Prevenzione e segue le professioni sanitarie: coerente con i panel medici. | G34: https://www.sanitainformazione.it/ | I34: redazione@sanitainformazione.it | J34: https://www.sanitainformazione.it/ (footer, “Per informazioni”; /contatti/ risponde 404; consultato 7 ott 2026)
A35: TrendSanità | B35: Testata online | C35: Nazionale | D35: innovazione in sanità, sanità digitale, valutazione delle tecnologie | E35: B | F35: Ha intervistato il Presidente (8 ottobre 2024) da media partner dei Taranto Biotech Days 2024; accetta comunicati a un indirizzo dedicato. | G35: https://trendsanita.it/ | H35: https://trendsanita.it/contatti/ | I35: redazione@trendsanita.it | J35: https://trendsanita.it/contatti/ (“inviarci i tuoi comunicati stampa”; consultato 7 ott 2026)
A36: Tuttoscuola | B36: Testata di informazione educativa | C36: Nazionale | D36: scuola, politiche educative, genitori | E36: B | F36: Informazione educativa con una sezione per i genitori: utile per il programma e per lo Showcase dell’11 dicembre. | G36: https://www.tuttoscuola.com/ | H36: https://www.tuttoscuola.com/contatti/ | I36: tuttoscuola@tuttoscuola.com | J36: https://www.tuttoscuola.com/contatti/ (voce “e-mail”; consultato 7 ott 2026)
A37: Radio Norba | B37: Radio regionale | C37: Puglia (sede a Conversano, BA) | D37: musica, intrattenimento, notizie, eventi | E37: B | F37: Radio regionale: canale per annunci e interviste ai relatori, soprattutto sportivi. | G37: https://radionorba.it/ | H37: https://radionorba.it/contatti/ | I37: radionorba@radionorba.it | J37: https://radionorba.it/contatti/ (voce “E-mail”, indirizzo generale; consultato 7 ott 2026)
A38: Corriere del Mezzogiorno (edizione Puglia) | B38: Quotidiano regionale del gruppo Corriere della Sera | C38: Puglia (sito bari.corriere.it) | D38: cronaca, politica, economia, cultura | E38: B | F38: Quotidiano regionale di un gruppo nazionale: porta la notizia oltre Taranto. | G38: https://bari.corriere.it/ | H38: https://www.corriere.it/scrivi/ | I38: corbari@rcs.it | J38: https://bari.corriere.it/ (box “Hai una storia da segnalare sul tuo territorio? Scrivici”); il modulo su corriere.it/scrivi ha la voce “Redazione Corriere del Mezzogiorno (Puglia)” (consultati 7 ott 2026)
A39: L’Edicola | B39: Quotidiano sfogliabile e sito di notizie (Ledi S.r.l., Bari) | C39: Puglia e Basilicata (Bari, BAT, Brindisi, Foggia, Lecce, Taranto) | D39: attualità, politica, cronaca, salute, cultura, sport | E39: B | F39: Ha seguito i Taranto Biotech Days 2024 (11 ottobre 2024); ha uno speciale Salute. | G39: https://ledicola.it/ | H39: https://ledicola.it/contatti/ | I39: redazione@ledieditori.it | J39: https://ledicola.it/contatti/ (“Scrivici a”; indirizzo protetto, decodificato; consultato 7 ott 2026)
A40: PugliaPress | B40: Portale di notizie regionale con PugliaPress TV | C40: Puglia, con sezioni per provincia (Taranto inclusa) | D40: cronaca, ambiente, economia, sport, eventi | E40: B | F40: Ha raccontato la nascita della Fondazione (22 aprile 2025); ha sezioni dedicate a Taranto. | G40: https://www.pugliapress.org/ | H40: https://www.pugliapress.org/contatti/ | I40: redazione@pugliapress.it | J40: https://www.pugliapress.org/contatti/ (“Puoi inviarci una email”; consultato 7 ott 2026)
...

Sheet Uscite
A1: Data | B1: Testata | C1: Tipo | D1: Area | E1: Titolo | F1: Autore | G1: Link | H1: Argomento | I1: Formato | J1: Cita la Fondazione | K1: Cita l’evento | L1: Cita sponsor | M1: Quali sponsor | N1: Tono | O1: Nella rassegna | P1: File | Q1: Note
A2: 44537 | B2: Oltre il Fatto | C2: online | E2: Premio Italia Giovane: il tarantino Guido Putignano tra i premiati dell’ottava edizione. | F2: Redazione | G2: https://www.oltreilfatto.it/2021/12/premio-italia-giovane-il-tarantino-guido-putignano-tra-i-premiati-dellottava-edizione/ | H2: Profilo del Presidente (2021) | I2: Articolo | J2: No | K2: No | L2: No | N2: Neutro | O2: No | Q2: Uso consigliato: interna; Precedente alla Fondazione. Trovato il 7 ottobre 2026 durante la revisione.; Verificata il 7 ottobre 2026
A3: 44540 | B3: TarantoTV Cittadella Radio (canale YouTube) | C3: TV | E3: 10/12/2021 - BUONGIORNO TARANTO - INTERVISTA GUIDO PUTIGNANO | G3: https://www.youtube.com/watch?v=kgB_22PQ6L4 | H3: Intervista al Presidente (2021) | I3: Servizio TV | J3: No | K3: No | L3: No | N3: Neutro | O3: No | Q3: Uso consigliato: interna; Precedente alla Fondazione.; Verificata il 7 ottobre 2026
A4: 44542 | B4: Oltre il Fatto | C4: online | E4: Premio Italia Giovane: intervista a Guido Putignano | F4: Francesco Ruggieri | G4: https://www.oltreilfatto.it/2021/12/premio-italia-giovane-intervista-a-guido-putignano/ | H4: Intervista al Presidente (2021) | I4: Articolo | J4: No | K4: No | L4: No | N4: Neutro | O4: No | Q4: Uso consigliato: interna; Precedente alla Fondazione. Stessa firma di A7 e C11 (R12). Trovato il 7 ottobre 2026 durante la revisione.; Verificata il 7 ottobre 2026
A5: 44638 | B5: Premio Italia Giovane (canale YouTube del premio) | C5: online | E5: Premio Italia Giovane 2021 - Intervista a Guido Putignano | G5: https://www.youtube.com/watch?v=HRJz70U5dFc | H5: Intervista al Presidente (2022) | I5: Articolo | J5: No | K5: No | L5: No | N5: Neutro | O5: No | Q5: Uso consigliato: interna; Tipo indicato: online (canale di un premio, non testata); Precedente alla Fondazione; non è una testata.; Verificata il 7 ottobre 2026
A6: 44851 | B6: La Gazzetta del Mezzogiorno | C6: quotidiano | E6: Taranto, il 20enne Guido Putignano nominato "il più influente in Italia" in Scienze Biologiche | F6: Redazione online | G6: https://www.lagazzettadelmezzogiorno.it/news/taranto/1362422/taranto-il-20enne-guido-putignano-nominato-il-piu-influente-in-italia-in-scienze-biologiche.html | H6: Profilo del Presidente (2022) | I6: Articolo | J6: No | K6: No | L6: No | N6: Neutro | O6: No | Q6: Uso consigliato: interna; Titolo con superlativo; precedente alla Fondazione.; Verificata il 7 ottobre 2026
A7: 44852 | B7: Buonasera24 (Taranto Buonasera) | C7: quotidiano | E7: Guido Putignano, a soli vent’anni eccellenza italiana | F7: La Redazione | G7: https://www.buonasera24.it/news/cronaca/452451/guido-putignano-a-soli-ventanni-eccellenza-italiana.html | H7: Profilo del Presidente (2022) | I7: Articolo | J7: No | K7: No | L7: No | N7: Neutro | O7: No | Q7: Uso consigliato: interna; Titolo enfatico; precedente alla Fondazione.; Verificata il 7 ottobre 2026
A8: 45547 | B8: Ordine dei Biologi della Puglia e della Basilicata | C8: istituzionale | E8: Dall’11 al 13 ottobre via alla prima edizione del “Taranto Biotech Days-BioNext” | G8: https://biologipugliabasilicata.it/dall11-al-13-ottobre-la-prima-edizione-del-tarantobiotechdays-bionext/ | H8: Taranto Biotech Days 2024 | I8: Articolo | J8: No | K8: No | L8: No | N8: Neutro | O8: No | Q8: Uso consigliato: interna; Conferma SafesPro come organizzatore del 2024.; Verificata il 7 ottobre 2026
A9: 45554 | B9: Buonasera24 (Taranto Buonasera) | C9: quotidiano | E9: Realizzare a Taranto un centro di ricerca per terapie cellulari | F9: La Redazione | G9: https://www.buonasera24.it/news/home/866072/realizzare-a-taranto-un-centro-di-ricerca-per-terapie-cellulari.html | H9: Taranto Biotech Days 2024 (annuncio) | I9: Articolo | J9: No | K9: No | L9: No | N9: Neutro | O9: Sì | Q9: Uso consigliato: pubblica, sezione storica; Il testo elenca il Comune di Taranto tra i coorganizzatori del 2024 e nomina persone fuori elenco: non riprendere.; Verificata il 7 ottobre 2026
A10: 45554 | B10: Oltre il Fatto | C10: online | E10: A Taranto un progetto per un centro di ricerca per terapie cellulari | F10: Francesco Ruggieri | G10: https://www.oltreilfatto.it/2024/09/a-taranto-un-progetto-per-un-centro-di-ricerca-per-terapie-cellulari/ | H10: Taranto Biotech Days 2024 (annuncio) | I10: Articolo | J10: No | K10: No | L10: No | N10: Neutro | O10: Sì | Q10: Uso consigliato: ripresa di A1, indicata nella scheda di A1; Come A1: cita il Comune tra i coorganizzatori e nomina persone fuori elenco. Stessa firma di A7 e C11 (R12). Assente da copertura.md, trovato il 7 ottobre 2026.; Verificata il 7 ottobre 2026
A11: 45555 | B11: Università di Bari, Dipartimento Jonico (uniba.it) | C11: istituzionale | E11: Taranto Biotech Days | G11: https://www.uniba.it/it/ricerca/dipartimenti/sistemi-giuridici-ed-economici/eventi/eventi-anno-2024/taranto-biotech-days | H11: Taranto Biotech Days 2024 | I11: Articolo | J11: No | K11: No | L11: No | N11: Neutro | O11: No | Q11: Uso consigliato: interna; Già in esterni.md F1.; Verificata il 7 ottobre 2026
A12: 45561 | B12: Osservatorio Terapie Avanzate | C12: periodico | E12: Taranto Biotech Days 2024. 11-13 ottobre 2024, Taranto | F12: Redazione | G12: https://www.osservatorioterapieavanzate.it/agenda/taranto-biotech-days-2024-11-13-ottobre-2024-taranto | H12: Taranto Biotech Days 2024 (agenda) | I12: Articolo | J12: No | K12: No | L12: No | N12: Neutro | O12: No | Q12: Uso consigliato: interna; Solo agenda; non nomina né la Fondazione né il Presidente.; Verificata il 7 ottobre 2026
A13: 45562 | B13: Biotecnologi Italiani (associazione nazionale) | C13: online | E13: Taranto Biotech Days | F13: Segreteria | G13: https://www.biotecnologitaliani.it/2024/09/27/taranto-biotech-days/ | H13: Taranto Biotech Days 2024 | I13: Articolo | J13: No | K13: No | L13: No | N13: Neutro | O13: No | Q13: Uso consigliato: interna; Tipo indicato: online (associazione); Verificata il 7 ottobre 2026
A14: 45573 | B14: TrendSanità | C14: periodico | E14: «Taranto per tre giorni capitale mondiale della biologia sintetica». La visione del ventenne Guido Putignano | F14: Cesare Buquicchio | G14: https://trendsanita.it/taranto-capitale-mondiale-biologia-sintetica-guido-putignano/ | H14: Intervista al Presidente; Taranto Biotech Days 2024 | I14: Articolo | J14: No | K14: No | L14: No | N14: Neutro | O14: No | Q14: Uso consigliato: interna; La testata si dichiara media partner dei Taranto Biotech Days. Titolo con superlativo; cita la NASA tra i relatori (dato non verificato).; Verificata il 7 ottobre 2026
A15: 45575 | B15: Oltre il Fatto | C15: online | E15: Taranto Biotech Days: l’11,12 e 13 ottobre in città i migliori esperti internazionali di biotecnologie | F15: Redazione | G15: https://www.oltreilfatto.it/2024/10/taranto-biotech-days-l1112-e-13-ottobre-in-citta-i-migliori-esperti-internazionali-di-biotecnologie/ | H15: Taranto Biotech Days 2024 (conferenza stampa) | I15: Articolo | J15: No | K15: No | L15: No | N15: Neutro | O15: No | Q15: Uso consigliato: interna; Titolo con superlativo. Elenca tra i presenti amministratori comunali e un consulente SafesPro il cui nome coincide con la firma di A7, A8, C11, D4, E1.; Verificata il 7 ottobre 2026
A16: 45575 | B16: CosmoPolis (WebTV) | C16: online | E16: Biotecnologie e terapie cellulari al Taranto Biotech Days | F16: CP | G16: https://www.cosmopolis.media/webtv/biotecnologie-e-terapie-cellulari-al-taranto-biotech-days/segreteria-di-redazione/ | H16: Taranto Biotech Days 2024 (video) | I16: Articolo | J16: No | K16: No | L16: No | N16: Neutro | O16: No | Q16: Uso consigliato: interna, dopo visione del video (DA CONFERMARE); Tipo indicato: TV (video online); Assente da copertura.md, trovato il 7 ottobre 2026.; Verificata il 7 ottobre 2026
A17: 45576 | B17: Noi Notizie | C17: online | E17: Taranto biotech days da oggi | F17: Agostino Quero | G17: https://www.noinotizie.it/11-10-2024/taranto-biotech-days-da-oggi/ | H17: Taranto Biotech Days 2024 (apertura) | I17: Articolo | J17: No | K17: No | L17: No | N17: Neutro | O17: Sì | Q17: Uso consigliato: pubblica, sezione storica (in alternativa ad A1); Come A1: cita il Comune tra i coorganizzatori del 2024.; Verificata il 7 ottobre 2026
A18: 45576 | B18: L’Edicola | C18: quotidiano | E18: I Biotech Days a Taranto, studiosi e startup a confronto: «Qui la ricerca cellulare» | F18: Vittorio Ricapito | G18: https://ledicola.it/news/taranto-iniziano-i-biotech-days-qui-la-ricerca-cellulare/ | H18: Taranto Biotech Days 2024 (apertura) | I18: Articolo | J18: No | K18: No | L18: No | N18: Neutro | O18: Sì | Q18: Uso consigliato: pubblica, sezione storica; L’Edicola (già L’Edicola del Sud) è un quotidiano: la gerenza (https://ledicola.it/gerenza/) riporta registrazione al Tribunale di Bari n. 22 del 12/10/2021 e lo stampatore. Il testo riporta un giudizio sul Presidente e dichiarazioni del 2024: non riprendere.; Verificata il 7 ottobre 2026
A19: 45576 | B19: Studio 100 | C19: TV | E19: Da oggi i Taranto Biotech Days, con esperti internazionali di biotecnologie | F19: Redazione | G19: https://www.studio100.it/2024/10/11/da-oggi-i-taranto-biotech-days-con-esperti-internazionali-di-biotecnologie/ | H19: Taranto Biotech Days 2024 (apertura) | I19: Servizio TV | J19: No | K19: No | L19: No | N19: Neutro | O19: Sì | Q19: Uso consigliato: pubblica, sezione storica; Verificata il 7 ottobre 2026
A20: 45577 | B20: Oltre il Fatto | C20: online | E20: Taranto Biotech Days: buona la prima | F20: Francesco Ruggieri | G20: https://www.oltreilfatto.it/2024/10/taranto-biotech-days-buona-la-prima/ | H20: Taranto Biotech Days 2024 (prima giornata) | I20: Articolo | J20: No | K20: No | L20: No | N20: Neutro | O20: Sì | Q20: Uso consigliato: pubblica, sezione storica; Riporta “circa 1.200” studenti e presenze istituzionali: non riprendere le cifre (vedi R5). Indipendenza (R12): la firma è quella di una persona che A7 indica tra i giornalisti che hanno condotto i lavori della prima giornata dei Taranto Biotech Days 2024 e che Studio 100, l’11 dicembre 2025, presenta come “della Fondazione BioErgoTech” (D6). DA CONFERMARE se pubblicarla.; Verificata il 7 ottobre 2026
A21: 45578 | B21: Oltre il Fatto | C21: online | E21: Taranto Biotech Days: Melucci lancia l’idea di una fondazione pubblico privato per il centro di ricerca | F21: Francesco Ruggieri | G21: https://www.oltreilfatto.it/2024/10/taranto-biotech-days-melucci-lancia-lidea-di-una-fondazione-pubblico-privato-per-il-centro-di-ricerca/ | H21: BioShot 2024; menzione speciale alla startup tarantina | I21: Articolo | J21: No | K21: No | L21: No | N21: Neutro | O21: No | Q21: Uso consigliato: interna; Il titolo nomina l’allora sindaco e un’ipotesi di fondazione pubblico privata: non usare in documenti pubblici. Indica nove startup (vedi R6).; Verificata il 7 ottobre 2026
A22: 45578 | B22: CosmoPolis (WebTV) | C22: online | E22: Innovazione e ricerca al Taranto Biotech Days 2024 | F22: CP | G22: https://www.cosmopolis.media/webtv/innovazione-e-ricerca-al-taranto-biotech-days-2024/segreteria-di-redazione/ | H22: Taranto Biotech Days 2024 (video) | I22: Articolo | J22: No | K22: No | L22: No | N22: Neutro | O22: No | Q22: Uso consigliato: interna, dopo visione del video (DA CONFERMARE); Tipo indicato: TV (video online); Assente da copertura.md, trovato il 7 ottobre 2026.; Verificata il 7 ottobre 2026
A23: 45579 | B23: Studio 100 | C23: TV | E23: Taranto Biotech Days: il bilancio complessivo di questi tre giorni all’insegna della bioscienza | F23: Redazione | G23: https://www.studio100.it/2024/10/14/taranto-biotech-days-il-bilancio-complessivo-di-questi-tre-giorni-allinsegna-della-bioscienza/ | H23: Taranto Biotech Days 2024 (bilancio) | I23: Servizio TV | J23: No | K23: No | L23: No | N23: Neutro | O23: No | Q23: Uso consigliato: pubblica, sezione storica (DA CONFERMARE): titolo neutro, inseribile nel gruppo 2024; Le interviste del servizio sono a persone fuori elenco: non nominarle. Assente da copertura.md, trovato il 7 ottobre 2026.; Verificata il 7 ottobre 2026
... A33: 45944 | B33: Buonasera24 (Taranto Buonasera) | C33: quotidiano | E33: Nasce la Fondazione bioERGOtech: tra intelligenza artificiale e terapie cellulari. Le foto | F33: Giulia Inversi | G33: https://www.buonasera24.it/gallery/cronaca/905068/nasce-la-fondazione-bioergotech-tra-intelligenza-artificiale-e-terapie-cellulari-le-foto.html | H33: Presentazione a Montecitorio (annuncio) | I33: Articolo | J33: Sì | K33: No | L33: No | N33: Neutro | O33: Sì | Q33: Uso consigliato: pubblica; Formato galleria fotografica. Obiettivi quinquennali non verificati (R10).; Verificata il 7 ottobre 2026
A34: 45944 | B34: Voce del Popolo Taranto | C34: online | E34: Un centro di ricerca per terapie cellulari a Taranto: nasce la Fondazione bioERGOtech | G34: https://www.vocedelpopolo.org/2025/10/14/centro-ricerca-terapie-cellulari-taranto/ | H34: Presentazione a Montecitorio (comunicato) | I34: Articolo | J34: Sì | K34: No | L34: No | N34: Neutro | O34: No | Q34: Uso consigliato: interna (ripresa di C1); Cifre non verificate (R5). Assente da copertura.md, trovato il 7 ottobre 2026.; Verificata il 7 ottobre 2026
A35: 45946 | B35: Noi Notizie | C35: online | E35: Un centro di ricerca per terapie cellulari a Taranto | F35: Agostino Quero | G35: https://www.noinotizie.it/16-10-2025/un-centro-di-ricerca-per-terapie-cellulari-a-taranto/ | H35: Presentazione a Montecitorio (comunicato) | I35: Articolo | J35: Sì | K35: No | L35: No | N35: Neutro | O35: No | Q35: Uso consigliato: interna; Pubblica un numero di cellulare personale come contatto stampa (non trascritto qui, R11) e un refuso (“evento del 19 ottobre”). Preferire C1.; Verificata il 7 ottobre 2026
A36: 45956 | B36: Secolo d’Italia | C36: online | E36: “Innovare per curare”: alla Camera la presentazione del progetto per formare “scienziati digitali” a Taranto | F36: Redazione | G36: https://www.secoloditalia.it/2025/10/innovare-per-curare-alla-camera-la-presentazione-del-progetto-per-formare-scienziati-digitali-a-taranto/ | H36: Presentazione a Montecitorio (annuncio) | I36: Articolo | J36: Sì | K36: No | L36: No | N36: Neutro | O36: Sì | Q36: Uso consigliato: pubblica; Il footer presenta la testata come “quotidiano on line della destra italiana” (R14). Cifre non verificate (R5, R10).; Verificata il 7 ottobre 2026
A37: 45957 | B37: Adnkronos (ripresa da Il Tempo) | C37: agenzia | E37: Innovazione: alla Camera la presentazione della fondazione bioERGOtech | F37: Adnkronos (firma: Il Tempo) | G37: https://www.iltempo.it/adnkronos/2025/10/27/news/innovazione-alla-camera-la-presentazione-della-fondazione-bioergotech-44744138/ | H37: Presentazione a Montecitorio (annuncio) | I37: Articolo | J37: Sì | K37: No | L37: No | N37: Neutro | O37: Sì | Q37: Uso consigliato: pubblica (voce principale del gruppo C); Unico lancio d’agenzia trovato. Nomina la Vice Presidente come cofondatrice e cifre non verificate (R5, R10).; Verificata il 7 ottobre 2026
A38: 45957 | B38: L’Identità | C38: quotidiano | E38: Ecco BioErgoTech: la ricerca medica riparte tra Ai e Mezzogiorno | F38: Pietro Pertosa | G38: https://www.lidentita.it/ecco-bioergotech-la-ricerca-medica-riparte-tra-ai-e-mezzogiorno/ | H38: Presentazione a Montecitorio (annuncio) | I38: Articolo | J38: Sì | K38: No | L38: No | N38: Neutro | O38: Sì | Q38: Uso consigliato: pubblica; Cifre non verificate (R5).; Verificata il 7 ottobre 2026
A39: 45957 | B39: CosmoPolis | C39: online | E39: Taranto, nasce bioERGOtech per realizzare un centro di ricerca | F39: CP | G39: https://www.cosmopolis.media/primo-piano/taranto-nasce-bioergotech-per-realizzare-un-centro-di-ricerca/segreteria-di-redazione/ | H39: Presentazione a Montecitorio (comunicato) | I39: Articolo | J39: Sì | K39: No | L39: No | N39: Neutro | O39: Sì | Q39: Uso consigliato: ripresa di C1, indicata nella scheda di C1; Cifre non verificate (R5).; Verificata il 7 ottobre 2026
A40: 45958 | B40: Camera dei Deputati, comunicazione.camera.it (Archivio Prima pagina) | C40: istituzionale | E40: Innovare per curare: clinica, ricerca e tecnologia in connessione | G40: https://comunicazione.camera.it/archivio-prima-pagina/19-53713 | H40: Convegno di presentazione a Montecitorio | I40: Articolo | J40: No | K40: No | L40: No | N40: Neutro | O40: No | Q40: Uso consigliato: interna; Conferma data, ora e sala del 29 ottobre 2025 (R8). Non indica patrocini: non dedurne alcuno.; Verificata il 7 ottobre 2026
A41: 45959 | B41: Innlifes | C41: periodico | E41: Guido Putignano (bioErgotech): l’ingegnere che sogna il sangue artificiale | F41: Anita Fiaschetti | G41: https://www.innlifes.com/biotech/guido-putignano-fondazione-bioergotech/ | H41: Intervista al Presidente; presentazione a Montecitorio | I41: Articolo | J41: Sì | K41: No | L41: No | N41: Neutro | O41: Sì | Q41: Uso consigliato: pubblica; Unica intervista estesa al Presidente nel periodo. Obiettivi quinquennali non verificati (R10).; Verificata il 7 ottobre 2026
A42: 45959 | B42: Adnkronos (ripresa da Civonline) | C42: agenzia | E42: Innovazione: Frassinetti, 'tecnologia sia al servizio della persona, la scuola deve formare' | F42: Redazione | G42: https://www.civonline.it/italia-e-mondo/innovazione-frassinetti-tecnologia-sia-al-servizio-della-persona-la-scuola-deve-formare-mtd1e3zg | H42: Presentazione a Montecitorio (cronaca) | I42: Articolo | J42: Sì | K42: No | L42: No | N42: Neutro | O42: No | Q42: Uso consigliato: interna; Il titolo nomina un membro del Governo e il testo nomina relatori fuori elenco: non usare in documenti pubblici. Conferma esternamente la Sala della Regina (R8).; Verificata il 7 ottobre 2026
A43: 45959 | B43: Studio 100 | C43: TV | E43: A Montecitorio la presentazione di bioERGOtech, il progetto che rilancia Taranto nella biomedicina | F43: Redazione | G43: https://www.studio100.it/2025/10/29/montecitorio-presentazione-bioergotech-taranto-biomedicina/ | H43: Presentazione a Montecitorio (intervista TV al Presidente) | I43: Servizio TV | J43: Sì | K43: No | L43: No | N43: Neutro | O43: Sì | Q43: Uso consigliato: pubblica, dopo visione del video (DA CONFERMARE); La pagina annuncia la presentazione “oggi” e dice che il direttore ne ha parlato con il Presidente: è un’intervista pubblicata la mattina del 29 ottobre (10:39), non un servizio sulla giornata. Il testo contiene l’età e un giudizio sul Presidente (R10): non riprendere.; Verificata il 7 ottobre 2026
A44: 45959 | B44: Camera dei Deputati, WebTV | C44: istituzionale | E44: Innovare per curare: clinica, ricerca e tecnologia in connessione | G44: https://webtv.camera.it/evento/29420 | H44: Video integrale del convegno | I44: Articolo | J44: No | K44: No | L44: No | N44: Neutro | O44: No | Q44: Uso consigliato: interna; Fonte utile per l’archivio video.; Verificata il 7 ottobre 2026
A45: 45961 | B45: Oltre il Fatto | C45: online | E45: BioErgoTech: Innovare per curare | F45: Francesco Ruggieri | G45: https://www.oltreilfatto.it/2025/10/bioergotech-innovare-per-curare/ | H45: Presentazione a Montecitorio (resoconto) | I45: Articolo | J45: Sì | K45: No | L45: No | N45: Neutro | O45: Sì | Q45: Uso consigliato: pubblica (titolo neutro); Il testo elenca presenze istituzionali (Comune, Camera di commercio, ASL, Regione, Governo) e imprese fuori elenco: non riprendere (R9, R13). Riprende l’apertura e ampie parti della nota della Fondazione pubblicata da C1. Indipendenza (R12): la firma è quella di una persona che A7 indica tra i giornalisti che hanno condotto i lavori della prima giornata dei Taranto Biotech Days 2024 e che Studio 100, l’11 dicembre 2025, presenta come “della Fondazione BioErgoTech” (D6). DA CONFERMARE se pubblicarla.; Verificata il 7 ottobre 2026
A46: 45964 | B46: Pianeta Salute Online | C46: periodico | E46: Fondazione BioErgoTech: nasce in Italia il nuovo polo che unisce biotecnologie e intelligenza artificiale per rivoluzionare la salute | F46: La Redazione di Pianeta Salute Online | G46: https://pianetasalute.online/fondazione-bioergotech-nasce-in-italia-il-nuovo-polo-che-unisce-biotecnologie-e-intelligenza-artificiale-per-rivoluzionare-la-salute/ | H46: Presentazione a Montecitorio (approfondimento) | I46: Articolo | J46: Sì | K46: No | L46: No | N46: Neutro | O46: No | Q46: Uso consigliato: interna; Titolo enfatico; scrive “oltre 1.500 esperti” per i Taranto Biotech Days (R5).; Verificata il 7 ottobre 2026
A47: 45964 | B47: Pianeta Salute TV (canale YouTube) | C47: TV | E47: Biotecnologie intelligenti: come Taranto diventa polo europeo di innovazione medica | G47: https://www.youtube.com/watch?v=xg3IeGTPRIE | H47: Presentazione a Montecitorio (servizio video) | I47: Servizio TV | J47: No | K47: No | L47: No | N47: Neutro | O47: No | Q47: Uso consigliato: interna, dopo visione del video (DA CONFERMARE); Verificata il 7 ottobre 2026
A48: 46003 | B48: Voce del Popolo Taranto | C48: online | E48: Taranto ospita l’evento “Cranio Tech: innovare per curare” | G48: https://www.vocedelpopolo.org/2025/12/12/taranto-ospita-evento-cranio-tech-innovare-per-curare/ | H48: Incontro di Taranto (annuncio) | I48: Articolo | J48: Sì | K48: No | L48: No | N48: Neutro | O48: No | Q48: Uso consigliato: interna; Titolo con nome di impresa fuori elenco. Data dell’incontro: venerdì 12 dicembre (contrasta con D4, D5: R7).; Verificata il 7 ottobre 2026
A49: 46004 | B49: NoiCamera, blog della Camera di commercio di Brindisi Taranto | C49: istituzionale | E49: Innovare per curare: a Taranto bioErgotech presenta i suoi progetti | F49: Francesca Sanesi | G49: https://www.noicamera.com/post/innovare-per-curare-a-taranto-bioergotech-presenta-i-suoi-progetti | H49: Incontro di Taranto (resoconto) | I49: Articolo | J49: Sì | K49: No | L49: No | N49: Neutro | O49: No | Q49: Uso consigliato: interna; Descrive la Camera di commercio come “partner della Fondazione e patrocinante dell’iniziativa” del dicembre 2025: non trasferire all’evento del 2026 (R9).; Verificata il 7 ottobre 2026
...

Sheet Riepilogo
A1: Riepilogo per la rassegna e per il report agli sponsor
A2: Calcolato dai fogli “Uscite” e “Media list”. Non scrivere qui.
A4: Uscite
A5: Uscite registrate | B5: =COUNTA(Uscite!$B$2:$B$400)
A6: di cui dal primo comunicato (13 ottobre 2026) | B6: =COUNTIFS(Uscite!$A$2:$A$400,">="&DATE(2026,10,13))
A7: di cui dal 10 dicembre 2026 | B7: =COUNTIFS(Uscite!$A$2:$A$400,">="&DATE(2026,12,10))
A8: Testate diverse | B8: =SUMPRODUCT((Uscite!$B$2:$B$400<>"")/COUNTIF(Uscite!$B$2:$B$400,Uscite!$B$2:$B$400&""))
A9: Che citano la Fondazione | B9: =COUNTIF(Uscite!$J$2:$J$400,"Sì")
A10: Che citano l’evento | B10: =COUNTIF(Uscite!$K$2:$K$400,"Sì")
A11: Che citano almeno uno sponsor | B11: =COUNTIF(Uscite!$L$2:$L$400,"Sì")
A12: Incluse nella rassegna | B12: =COUNTIF(Uscite!$O$2:$O$400,"Sì")
A13: Per tipo
A14: quotidiano | B14: =COUNTIF(Uscite!$C$2:$C$400,"quotidiano")
A15: online | B15: =COUNTIF(Uscite!$C$2:$C$400,"online")
A16: TV | B16: =COUNTIF(Uscite!$C$2:$C$400,"TV")
A17: radio | B17: =COUNTIF(Uscite!$C$2:$C$400,"radio")
A18: agenzia | B18: =COUNTIF(Uscite!$C$2:$C$400,"agenzia")
A19: periodico | B19: =COUNTIF(Uscite!$C$2:$C$400,"periodico")
A20: istituzionale | B20: =COUNTIF(Uscite!$C$2:$C$400,"istituzionale")
A21: Per formato
A22: Articolo | B22: =COUNTIF(Uscite!$I$2:$I$400,"Articolo")
A23: Intervista | B23: =COUNTIF(Uscite!$I$2:$I$400,"Intervista")
A24: Servizio TV | B24: =COUNTIF(Uscite!$I$2:$I$400,"Servizio TV")
A25: Servizio radio | B25: =COUNTIF(Uscite!$I$2:$I$400,"Servizio radio")
A26: Breve | B26: =COUNTIF(Uscite!$I$2:$I$400,"Breve")
A27: Post | B27: =COUNTIF(Uscite!$I$2:$I$400,"Post")
A28: Comunicato ripreso | B28: =COUNTIF(Uscite!$I$2:$I$400,"Comunicato ripreso")
A29: Media list
A30: Testate in elenco | B30: =COUNTA('Media list'!$A$2:$A$120)
A31: di priorità A | B31: =COUNTIF('Media list'!$E$2:$E$120,"A")
A32: Comunicato inviato | B32: =COUNT('Media list'!$N$2:$N$120)
A33: Nota per le redazioni inviata | B33: =COUNT('Media list'!$O$2:$O$120)
A34: Testate che hanno pubblicato | B34: =COUNTIF('Media list'!$P$2:$P$120,"Pubblicato")
A35: Giornalisti accreditati (testate) | B35: =COUNTIF('Media list'!$Q$2:$Q$120,"Sì")
